<mujoco model="unnamed_model">
  <compiler autolimits="true" angle="radian"/>
  <option integrator="implicitfast"/>
  <default>
    <default class="/"/>
    <default class="xarm6/">
      <default class="xarm6/xarm6">
        <joint axis="0 0 1" range="-6.2831900000000003 6.2831900000000003" frictionloss="1"/>
        <geom type="mesh" material="xarm6/white"/>
        <site group="4" rgba="1 0 0 1" size="0.001"/>
        <general ctrlrange="-6.2831900000000003 6.2831900000000003" biastype="affine"/>
        <default class="xarm6/size1">
          <joint damping="10"/>
          <general forcerange="-50 50" gainprm="1500" biasprm="0 -1500 -150"/>
        </default>
        <default class="xarm6/size2">
          <joint damping="5"/>
          <general forcerange="-30 30" gainprm="1000" biasprm="0 -1000 -100"/>
        </default>
        <default class="xarm6/size3">
          <joint damping="2"/>
          <general forcerange="-20 20" gainprm="800" biasprm="0 -800 -80"/>
        </default>
        <default class="xarm6/follower">
          <joint solreflimit="0.0050000000000000001 1"/>
        </default>
      </default>
    </default>
  </default>
  <asset>
    <material name="xarm6/white" class="xarm6/" rgba="1 1 1 1"/>
    <material name="xarm6/gray" class="xarm6/" rgba="0.753 0.753 0.753 1"/>
    <material name="xarm6/black" class="xarm6/" rgba="0.14899999999999999 0.14899999999999999 0.14899999999999999 1"/>
    <mesh name="xarm6/link_base" class="xarm6/" file="link_base-d9155048b273bf169b05f38a3046e2273d413f70.stl"/>
    <mesh name="xarm6/link1" class="xarm6/" file="link1-57c408f3a98cfa635dc60299c03e09da71510788.stl"/>
    <mesh name="xarm6/link2" class="xarm6/" file="link2-6ec04b4c8ae94dea2e95239036d7432b886669af.stl"/>
    <mesh name="xarm6/link3" class="xarm6/" file="link3-e0226bbcb039c219df1b92f77fa0d6ca2b5a0d3d.stl"/>
    <mesh name="xarm6/link4" class="xarm6/" file="link4-b3637ec9841e4965b0a361d4540f8d9038a6523f.stl"/>
    <mesh name="xarm6/link5" class="xarm6/" file="link5-ba029c711717f9b57a2d1e582b3eb051bd6f8da7.stl"/>
    <mesh name="xarm6/link6" class="xarm6/" file="link6-50f8bb02f82e5ac05af8fe52c738d9348852e615.stl"/>
    <mesh name="xarm6/end_tool" class="xarm6/" file="end_tool-fba88989e12d718c4e6776399e40b7df4c85f363.stl"/>
    <mesh name="xarm6/link_base_bio_gripper" class="xarm6/" file="link_base_bio_gripper-6cf0a2f346a706dca477d85cf4ccea4eaa726256.stl"/>
    <mesh name="xarm6/left_finger" class="xarm6/" file="left_finger-293e0c49b584d7283c1978119d910593021425db.stl"/>
    <mesh name="xarm6/right_finger" class="xarm6/" file="right_finger-016533440312281cebcb48d92506ec7ddc1ed1b3.stl"/>
  </asset>
  <worldbody>
    <body name="xarm6/">
      <body name="xarm6/link_base" childclass="xarm6/xarm6" pos="0 0 0.09103">
        <inertial pos="0 0 0.09103" quat="0.69684299999999999 0.20175999999999999 0.10388 0.68037599999999998" mass="2.7000000000000002" diaginertia="0.00382023 0.0033528199999999998 0.0016772499999999999"/>
        <geom name="xarm6//unnamed_geom_0" mesh="xarm6/link_base"/>
        <body name="xarm6/link1" pos="0 0 0.26000000000000001">
          <inertial pos="0.00022000000000000001 0.029510000000000002 -0.0124" quat="0.97895299999999996 -0.202769 -0.0044161699999999996 -0.022726400000000001" mass="2.3814000000000002" diaginertia="0.00569127 0.0053338400000000003 0.0029386500000000001"/>
          <joint name="xarm6/joint1" class="xarm6/size1"/>
          <geom name="xarm6//unnamed_geom_1" mesh="xarm6/link1"/>
          <body name="xarm6/link2" pos="0 0 0" quat="1 -1 0 0">
            <inertial pos="0.038809999999999997 -0.22783 0.034959999999999998" quat="0.50197999999999998 0.86482999999999999 -0.00778841 0.0048328499999999996" mass="2.2675000000000001" diaginertia="0.00959898 0.0093771700000000006 0.00201315"/>
            <joint name="xarm6/joint2" class="xarm6/size1" range="-2.0590000000000002 2.0943999999999998"/>
            <geom name="xarm6//unnamed_geom_2" mesh="xarm6/link2"/>
            <body name="xarm6/link3" pos="0.053499999999999999 -0.28449999999999998 0" quat="1 0 0 0">
              <inertial pos="0.07041 0.11631 0.010699999999999999" quat="0.91381900000000005 0.289775 0.28148099999999998 -0.041645500000000002" mass="1.875" diaginertia="0.0035172100000000002 0.0029408899999999998 0.00195868"/>
              <joint name="xarm6/joint3" class="xarm6/size2" range="-3.927 0.19198000000000001"/>
              <geom name="xarm6//unnamed_geom_3" mesh="xarm6/link3"/>
              <body name="xarm6/link4" pos="0.077499999999999999 0.34250000000000003 0" quat="1 -1 0 0">
                <inertial pos="-0.00018000000000000001 0.017979999999999999 -0.02291" quat="0.42210799999999998 0.85202599999999995 -0.126025 0.28283199999999997" mass="1.3191999999999999" diaginertia="0.00657137 0.0064794800000000001 0.0018676299999999999"/>
                <joint name="xarm6/joint4" class="xarm6/size2" range="-6.2831799999999998 6.2831799999999998"/>
                <geom name="xarm6//unnamed_geom_4" mesh="xarm6/link4"/>
                <body name="xarm6/link5" pos="0 0 0" quat="1 1 0 0">
                  <inertial pos="0.065100000000000005 0.030960000000000001 0.00315" quat="0.99931099999999995 -0.030445699999999999 0.00057706700000000001 0.0212082" mass="1.3385400000000001" diaginertia="0.0053472900000000002 0.0049907600000000003 0.0013489000000000001"/>
                  <joint name="xarm6/joint5" class="xarm6/size2" range="-1.6929700000000001 3.1415899999999999"/>
                  <geom name="xarm6//unnamed_geom_5" mesh="xarm6/link5"/>
                  <body name="xarm6/link6" quat="1 -1 0 0">
                    <inertial pos="0.075999999999999998 0.097000000000000003 0" quat="-0.217672 0.77241899999999997 0.16258 0.57406900000000005" mass="0.17000000000000001" diaginertia="0.0024542100000000001 0.00221646 0.00107273"/>
                    <joint name="xarm6/joint6" class="xarm6/size3" range="-6.2831799999999998 6.2831799999999998"/>
                    <geom name="xarm6//unnamed_geom_6" mesh="xarm6/link6"/>
                    <body name="xarm6/bio_gripper_base_link" pos="0.075999999999999998 0 0.069000000000000006" quat="1 0 0 0">
                      <inertial pos="0.016178999999999999 -2.3910999999999999e-05 0.023897000000000002" quat="1 0 0 0" mass="0.38836999999999999" diaginertia="0.00088398000000000003 0.00018255999999999999 0.00094673000000000001"/>
                      <geom name="xarm6//unnamed_geom_7" mesh="xarm6/link_base_bio_gripper"/>
                      <body name="xarm6/left_finger" pos="0.058999999999999997 0 0.027">
                        <inertial pos="0.021846000000000001 -0.0276 0.011911" quat="1 0 0 0" mass="0.012104999999999999" diaginertia="3.7322e-06 1.7439999999999999e-05 1.7774999999999998e-05"/>
                        <joint name="xarm6/left_finger_joint" class="xarm6/follower" type="slide" axis="0 1 0" range="-0.040000000000000001 0"/>
                        <geom name="xarm6//unnamed_geom_8" material="xarm6/white" mesh="xarm6/left_finger"/>
                      </body>
                      <body name="xarm6/right_finger" pos="0.058999999999999997 0 0.027">
                        <inertial pos="0.020369999999999999 0.027564999999999999 0.010274" quat="1 0 0 0" mass="0.012068000000000001" diaginertia="4.1412999999999996e-06 1.6115000000000001e-05 1.6032000000000002e-05"/>
                        <joint name="xarm6/right_finger_joint" class="xarm6/follower" type="slide" axis="0 1 0" range="0 0.040000000000000001"/>
                        <geom name="xarm6//unnamed_geom_9" material="xarm6/white" mesh="xarm6/right_finger"/>
                      </body>
                      <body name="xarm6/link_tcp" pos="0.13500000000000001 0 0.055">
                        <site name="xarm6/tcp" size="0.001" pos="0 0 0"/>
                      </body>
                    </body>
                  </body>
                </body>
              </body>
            </body>
          </body>
        </body>
      </body>
    </body>
  </worldbody>
  <contact>
    <exclude name="xarm6//unnamed_contact_0" body1="xarm6/left_finger" body2="xarm6/right_finger"/>
    <exclude name="xarm6//unnamed_contact_1" body1="xarm6/left_finger" body2="xarm6/bio_gripper_base_link"/>
    <exclude name="xarm6//unnamed_contact_2" body1="xarm6/right_finger" body2="xarm6/bio_gripper_base_link"/>
  </contact>
  <equality>
    <joint name="xarm6//unnamed_equality_0" class="xarm6/" solref="0.0050000000000000001 1" joint1="xarm6/left_finger_joint" joint2="xarm6/right_finger_joint" polycoef="0 -1 0 0 0"/>
  </equality>
  <tendon>
    <fixed name="xarm6/split" class="xarm6/">
      <joint joint="xarm6/right_finger_joint" coef="0.5"/>
      <joint joint="xarm6/left_finger_joint" coef="0.5"/>
    </fixed>
  </tendon>
  <actuator>
    <general name="xarm6/act1" class="xarm6/size1" joint="xarm6/joint1"/>
    <general name="xarm6/act2" class="xarm6/size1" ctrlrange="-2.0590000000000002 2.0943999999999998" joint="xarm6/joint2"/>
    <general name="xarm6/act3" class="xarm6/size2" ctrlrange="-3.92699 0.19198599999999999" joint="xarm6/joint3"/>
    <general name="xarm6/act4" class="xarm6/size2" joint="xarm6/joint4"/>
    <general name="xarm6/act5" class="xarm6/size3" ctrlrange="-1.6929700000000001 3.1415899999999999" joint="xarm6/joint5"/>
    <general name="xarm6/act6" class="xarm6/size3" joint="xarm6/joint6"/>
    <general name="xarm6/gripper" class="xarm6/" ctrlrange="0 255" forcerange="-50 50" tendon="xarm6/split" biastype="affine" gainprm="0.33300000000000002" biasprm="0 -100 -10"/>
  </actuator>
  <keyframe>
    <key name="xarm6/home" qpos="0 -0.247 0 0.90900000000000003 0 1.1564399999999999 0 0" ctrl="0 -0.247 0 0.90900000000000003 0 1.1564399999999999 0"/>
  </keyframe>
</mujoco>
