<mujoco model="xarm6">
  <compiler angle="radian" autolimits="true" meshdir="assets"/>
  <option integrator="implicitfast"/>
  <asset>
    <material name="white" rgba="1 1 1 1"/>
    <material name="gray" rgba="0.753 0.753 0.753 1"/>
    <material name="black" rgba="0.149 0.149 0.149 1"/>
    <mesh file="link_base.stl"/>
    <mesh file="link1.stl"/>
    <mesh file="link2.stl"/>
    <mesh file="link3.stl"/>
    <mesh file="link4.stl"/>
    <mesh file="link5.stl"/>
    <mesh file="link6.stl"/>
    <mesh file="end_tool.stl"/>
    <mesh file="link_base_bio_gripper.stl"/>
    <mesh file="left_finger.stl"/>
    <mesh file="right_finger.stl"/>
  </asset>
  
  <default>
    <default class="xarm6">
      <geom type="mesh" material="white"/>
      <joint axis="0 0 1" range="-6.28319 6.28319" frictionloss="1"/>
      <general biastype="affine" ctrlrange="-6.28319 6.28319"/>
      <default class="size1">
        <joint damping="10"/>
        <general gainprm="1500" biasprm="0 -1500 -150" forcerange="-50 50"/>
      </default>
      <default class="size2">
        <joint damping="5"/>
        <general gainprm="1000" biasprm="0 -1000 -100" forcerange="-30 30"/>
      </default>
      <default class="size3">
        <joint damping="2"/>
        <general gainprm="800" biasprm="0 -800 -80" forcerange="-20 20"/>
      </default>
      <default class="follower">
        <joint solreflimit="0.005 1"/>
      </default>
      <site size="0.001" rgba="1 0 0 1" group="4"/>
    </default>
  </default>
  
  <worldbody>
    <body name="link_base" pos="0 0 0.09103" childclass="xarm6">
      <inertial pos="0 0 0.09103" quat="0.696843 0.20176 0.10388 0.680376" mass="2.7" diaginertia="0.00382023 0.00335282 0.00167725"/>
      <geom mesh="link_base"/>
      <body name="link1" pos="0 0 0.26">
        <inertial pos="0.00022 0.02951 -0.0124" quat="0.978953 -0.202769 -0.00441617 -0.0227264" mass="2.3814" diaginertia="0.00569127 0.00533384 0.00293865"/>
        <joint name="joint1" class="size1"/>
        <geom mesh="link1"/>
        <body name="link2" pos="0 0 0" quat="1 -1 0 0">
          <inertial pos="0.03881 -0.22783 0.03496" quat="0.50198 0.86483 -0.00778841 0.00483285" mass="2.2675" diaginertia="0.00959898 0.00937717 0.00201315"/>
          <joint name="joint2" range="-2.059 2.0944" class="size1"/>
          <geom mesh="link2"/>
          <body name="link3" pos="0.0535 -0.2845 0" quat="1 0 0 0">
            <inertial pos="0.07041 0.11631 0.0107" quat="0.913819 0.289775 0.281481 -0.0416455" mass="1.875" diaginertia="0.00351721 0.00294089 0.00195868"/>
            <joint name="joint3" range="-3.927 0.19198" class="size2"/>
            <geom mesh="link3"/>
            <body name="link4" pos="0.0775 0.3425 0" quat="1 -1 0 0">
              <inertial pos="-0.00018 0.01798 -0.02291" quat="0.422108 0.852026 -0.126025 0.282832" mass="1.3192" diaginertia="0.00657137 0.00647948 0.00186763"/>
              <joint name="joint4" range="-6.28318 6.28318" class="size2"/>
              <geom mesh="link4"/>
              <body name="link5" pos="0 0 0" quat="1 1 0 0">
                <inertial pos="0.0651 0.03096 0.00315" quat="0.999311 -0.0304457 0.000577067 0.0212082" mass="1.33854" diaginertia="0.00534729 0.00499076 0.0013489"/>
                <joint name="joint5" range="-1.69297 3.14159" class="size2"/>
                <geom mesh="link5"/>
                <body name="link6" quat="1 -1 0 0">
                  <inertial pos="0.076 0.097 0" quat="-0.217672 0.772419 0.16258 0.574069" mass="0.17" diaginertia="0.00245421 0.00221646 0.00107273"/>
                  <joint name="joint6" range="-6.28318 6.28318" class="size3"/>
                  <geom mesh="link6"/>
                  <body name="bio_gripper_base_link" pos="0 0 0" quat="1 0 0 0">
                    <body name="visual_offset" pos="0.076 0 0.069">
                      <inertial pos="0.016179 -2.3911e-05 0.023897" quat="1 0 0 0" mass="0.38837" diaginertia="0.00088398 0.00018256 0.00094673"/>
                      <geom mesh="link_base_bio_gripper"/>
                      <body name="left_finger" pos="0.059 0 0.027">
                        <inertial pos="0.021846 -0.0276 0.011911" quat="1 0 0 0" mass="0.012105" diaginertia="3.7322e-06 1.744e-05 1.7775e-05"/>
                        <joint name="left_finger_joint" type="slide" axis="0 1 0" range="0 0.2" class="follower"/>
                        <geom material="white" mesh="left_finger"/>
                      </body>
                      <body name="right_finger" pos="0.059 0 0.027">
                        <inertial pos="0.02037 0.027565 0.010274" quat="1 0 0 0" mass="0.012068" diaginertia="4.1413e-06 1.6115e-05 1.6032e-05"/>
                        <joint name="right_finger_joint" type="slide" axis="0 -1 0" range="-0.2 0" class="follower"/>
                        <geom material="white" mesh="right_finger"/>
                      </body>
                      <body name="link_tcp" pos="0.135 0 0.055">
                        <site name="tcp" pos="0 0 0" size="0.001"/>
                      </body>
                    </body>
                  </body>
                </body>
              </body>
            </body>
          </body>
        </body>
      </body>
    </body>
  </worldbody>
  
  <contact>
    <exclude body1="left_finger" body2="right_finger"/>
    <exclude body1="left_finger" body2="bio_gripper_base_link"/>
    <exclude body1="right_finger" body2="bio_gripper_base_link"/>
  </contact>

  <tendon>
    <fixed name="split">
      <joint joint="right_finger_joint" coef="0.5"/>
      <joint joint="left_finger_joint" coef="0.5"/>
    </fixed>
  </tendon>
  
  <equality>
    <joint joint1="left_finger_joint" joint2="right_finger_joint" polycoef="0 1 0 0 0"/>
  </equality>
  
  <actuator>
    <general name="act1" joint="joint1" class="size1"/>
    <general name="act2" joint="joint2" class="size1" ctrlrange="-2.059 2.0944"/>
    <general name="act3" joint="joint3" class="size2" ctrlrange="-3.92699 0.191986"/>
    <general name="act4" joint="joint4" class="size2"/>
    <general name="act5" joint="joint5" class="size3" ctrlrange="-1.69297 3.14159"/>
    <general name="act6" joint="joint6" class="size3"/>
    <general name="gripper" tendon="split" forcerange="-50 50" ctrlrange="0 255" biastype="affine" gainprm="0.333" biasprm="0 -100 -10"/>
  </actuator>
  
  <keyframe>
    <!-- qpos: 6 arm joints + 6 gripper/finger joints = 12 values -->
    <!-- Example: [joint1 joint2 joint3 joint4 joint5 joint6 left_driver_joint left_finger_joint left_inner_knuckle_joint right_driver_joint right_finger_joint right_inner_knuckle_joint] -->
    <key name="home" qpos="0 -.247 0 .909 0 1.15644 0 0" ctrl="0 -.247 0 .909 0 1.15644 0"/>
  </keyframe>
</mujoco>
